# Coverage Report

Total executable lines: 2
Covered lines: 2
Missed lines: 0
Coverage percentage: 100.00%

## Source Code with Coverage

```python
1: ✓ def ifPowerOfFour(n):
2: ✓     return n > 0 and (n & (n - 1)) == 0 and n % 3 == 1
```

## Complete Test File

```python
def ifPowerOfFour(n):
    return n > 0 and (n & (n - 1)) == 0 and n % 3 == 1

def run_tests():
    test_results = []
    # Test case 1
    try:
        result = ifPowerOfFour(0)
        assert result == False, f"Test 1 failed: got {result}, expected {False}"
        print(f"Test 1 passed")
        test_results.append(True)
    except Exception as e:
        print(f"Test 1 failed: {e}")
        test_results.append(False)

    # Test case 2
    try:
        result = ifPowerOfFour(1)
        assert result == True, f"Test 2 failed: got {result}, expected {True}"
        print(f"Test 2 passed")
        test_results.append(True)
    except Exception as e:
        print(f"Test 2 failed: {e}")
        test_results.append(False)

    # Test case 3
    try:
        result = ifPowerOfFour(2)
        assert result == False, f"Test 3 failed: got {result}, expected {False}"
        print(f"Test 3 passed")
        test_results.append(True)
    except Exception as e:
        print(f"Test 3 failed: {e}")
        test_results.append(False)

    # Test case 4
    try:
        result = ifPowerOfFour(3)
        assert result == False, f"Test 4 failed: got {result}, expected {False}"
        print(f"Test 4 passed")
        test_results.append(True)
    except Exception as e:
        print(f"Test 4 failed: {e}")
        test_results.append(False)

    # Test case 5
    try:
        result = ifPowerOfFour(4)
        assert result == True, f"Test 5 failed: got {result}, expected {True}"
        print(f"Test 5 passed")
        test_results.append(True)
    except Exception as e:
        print(f"Test 5 failed: {e}")
        test_results.append(False)

    # Test case 6
    try:
        result = ifPowerOfFour(8)
        assert result == False, f"Test 6 failed: got {result}, expected {False}"
        print(f"Test 6 passed")
        test_results.append(True)
    except Exception as e:
        print(f"Test 6 failed: {e}")
        test_results.append(False)

    # Test case 7
    try:
        result = ifPowerOfFour(16)
        assert result == True, f"Test 7 failed: got {result}, expected {True}"
        print(f"Test 7 passed")
        test_results.append(True)
    except Exception as e:
        print(f"Test 7 failed: {e}")
        test_results.append(False)

    # Test case 8
    try:
        result = ifPowerOfFour(64)
        assert result == True, f"Test 8 failed: got {result}, expected {True}"
        print(f"Test 8 passed")
        test_results.append(True)
    except Exception as e:
        print(f"Test 8 failed: {e}")
        test_results.append(False)

    # Test case 9
    try:
        result = ifPowerOfFour(95)
        assert result == False, f"Test 9 failed: got {result}, expected {False}"
        print(f"Test 9 passed")
        test_results.append(True)
    except Exception as e:
        print(f"Test 9 failed: {e}")
        test_results.append(False)

    # Test case 10
    try:
        result = ifPowerOfFour(100)
        assert result == False, f"Test 10 failed: got {result}, expected {False}"
        print(f"Test 10 passed")
        test_results.append(True)
    except Exception as e:
        print(f"Test 10 failed: {e}")
        test_results.append(False)

    # Test case 11
    try:
        result = ifPowerOfFour(256)
        assert result == True, f"Test 11 failed: got {result}, expected {True}"
        print(f"Test 11 passed")
        test_results.append(True)
    except Exception as e:
        print(f"Test 11 failed: {e}")
        test_results.append(False)

    # Test case 12
    try:
        result = ifPowerOfFour(520)
        assert result == False, f"Test 12 failed: got {result}, expected {False}"
        print(f"Test 12 passed")
        test_results.append(True)
    except Exception as e:
        print(f"Test 12 failed: {e}")
        test_results.append(False)

    # Test case 13
    try:
        result = ifPowerOfFour(1024)
        assert result == True, f"Test 13 failed: got {result}, expected {True}"
        print(f"Test 13 passed")
        test_results.append(True)
    except Exception as e:
        print(f"Test 13 failed: {e}")
        test_results.append(False)

    return test_results

if __name__ == '__main__':
    results = run_tests()
    print(f"\n{sum(results)}/{len(results)} tests passed")

```
